<sdf version='1.4'>
  <world name='default'>
    <model name='heightmap'>
      <static>1</static>
      <link name='link'>
        <collision name='collision'>
          <geometry>
            <heightmap>
              <uri>model://map3.png</uri>
              <size>15 15 2</size>
              <pos>0 0 0</pos>
              <texture>
                <size>10</size>
                <diffuse>__default__</diffuse>
                <normal>__default__</normal>
              </texture>
              <blend>
                <min_height>0</min_height>
                <fade_dist>0</fade_dist>
              </blend>
            </heightmap>
          </geometry>
          <max_contacts>10</max_contacts>
          <surface>
            <bounce/>
            <friction>
              <ode/>
            </friction>
            <contact>
              <ode/>
            </contact>
          </surface>
        </collision>
        <visual name='visual'>
          <geometry>
            <heightmap>
              <uri>model://map3.png</uri>
              <size>15 15 2</size>
              <pos>0 0 0</pos>
              <texture>
                <size>10</size>
                <diffuse>__default__</diffuse>
                <normal>__default__</normal>
              </texture>
              <blend>
                <min_height>0</min_height>
                <fade_dist>0</fade_dist>
              </blend>
            </heightmap>
          </geometry>
        </visual>
        <velocity_decay>
          <linear>0</linear>
          <angular>0</angular>
        </velocity_decay>
        <self_collide>0</self_collide>
        <kinematic>0</kinematic>
        <gravity>1</gravity>
      </link>
    </model>
    <physics type='ode'>
      <max_step_size>0.005</max_step_size>
      <real_time_factor>1</real_time_factor>
      <real_time_update_rate>200</real_time_update_rate>
      <gravity>0 0 -9.8</gravity>
    </physics>
    <scene>
      <ambient>0.4 0.4 0.4 1</ambient>
      <background>0.7 0.7 0.7 1</background>
      <shadows>1</shadows>
    </scene>
    <spherical_coordinates>
      <surface_model>EARTH_WGS84</surface_model>
      <latitude_deg>0</latitude_deg>
      <longitude_deg>0</longitude_deg>
      <elevation>0</elevation>
      <heading_deg>0</heading_deg>
    </spherical_coordinates>
    <model name='teresa_robot'>
      <link name='base_link'>
        <pose>0 0 0 0 -0 0</pose>
        <inertial>
          <pose>3.77114e-19 0 0.33437 0 -0 0</pose>
          <mass>9.2</mass>
          <inertia>
            <ixx>3.0011</ixx>
            <ixy>0</ixy>
            <ixz>1.16008e-18</ixz>
            <iyy>3.01236</iyy>
            <iyz>0</iyz>
            <izz>3.01126</izz>
          </inertia>
        </inertial>
        <collision name='base_link_collision'>
          <pose>0 0 0.336 0 0 -1.5708</pose>
          <geometry>
            <mesh>
              <scale>0.1 0.1 0.1</scale>
              <uri>/home/parallels/teresa_catkin_pkgs/src/teresa_gazebo/meshes/teresa_body.dae</uri>
            </mesh>
          </geometry>
          <surface>
            <contact>
              <ode/>
            </contact>
            <friction>
              <ode>
                <mu>0</mu>
                <mu2>0</mu2>
              </ode>
            </friction>
            <bounce/>
          </surface>
          <max_contacts>10</max_contacts>
        </collision>
        <visual name='base_link_visual'>
          <pose>0 0 0.336 0 0 -1.5708</pose>
          <geometry>
            <mesh>
              <scale>0.1 0.1 0.1</scale>
              <uri>/home/parallels/teresa_catkin_pkgs/src/teresa_gazebo/meshes/teresa_body.dae</uri>
            </mesh>
          </geometry>
          <material>
            <script>
              <name>Gazebo/Blue</name>
              <uri>__default__</uri>
            </script>
          </material>
        </visual>
        <visual name='base_link_visual_laserback'>
          <pose>-0.23725 0 0.261 0 -0 -3.14159</pose>
          <geometry>
            <mesh>
              <scale>1 1 1</scale>
              <uri>/home/parallels/teresa_catkin_pkgs/src/teresa_gazebo/meshes/hokuyo.dae</uri>
            </mesh>
          </geometry>
        </visual>
        <visual name='base_link_visual_laserfront'>
          <pose>0.23725 0 0.261 0 -0 0</pose>
          <geometry>
            <mesh>
              <scale>1 1 1</scale>
              <uri>/home/parallels/teresa_catkin_pkgs/src/teresa_gazebo/meshes/hokuyo.dae</uri>
            </mesh>
          </geometry>
        </visual>
        <velocity_decay>
          <linear>0</linear>
          <angular>0</angular>
        </velocity_decay>
        <velocity_decay>
          <linear>0</linear>
          <angular>0</angular>
        </velocity_decay>
        <sensor name='hokuyo_back_sensor' type='ray'>
          <visualize>0</visualize>
          <update_rate>40</update_rate>
          <ray>
            <scan>
              <horizontal>
                <samples>720</samples>
                <resolution>1</resolution>
                <min_angle>-1.5708</min_angle>
                <max_angle>1.5708</max_angle>
              </horizontal>
            </scan>
            <range>
              <min>0.1</min>
              <max>4</max>
              <resolution>0.01</resolution>
            </range>
            <noise>
              <type>gaussian</type>
              <mean>0</mean>
              <stddev>0.01</stddev>
            </noise>
          </ray>
          <plugin name='gazebo_ros_head_hokuyo_controller' filename='libgazebo_ros_laser.so'>
            <topicName>/scanback</topicName>
            <frameName>laserback</frameName>
            <robotNamespace>/</robotNamespace>
          </plugin>
          <pose>-0.23725 0 0.261 0 -0 -3.14159</pose>
        </sensor>
        <gravity>1</gravity>
        <velocity_decay>
          <linear>0</linear>
          <angular>0</angular>
        </velocity_decay>
        <self_collide>0</self_collide>
        <sensor name='hokuyo_front_sensor' type='ray'>
          <visualize>0</visualize>
          <update_rate>40</update_rate>
          <ray>
            <scan>
              <horizontal>
                <samples>720</samples>
                <resolution>1</resolution>
                <min_angle>-1.5708</min_angle>
                <max_angle>1.5708</max_angle>
              </horizontal>
            </scan>
            <range>
              <min>0.1</min>
              <max>4</max>
              <resolution>0.01</resolution>
            </range>
            <noise>
              <type>gaussian</type>
              <mean>0</mean>
              <stddev>0.01</stddev>
            </noise>
          </ray>
          <plugin name='gazebo_ros_head_hokuyo_controller' filename='libgazebo_ros_laser.so'>
            <topicName>/scanfront</topicName>
            <frameName>laserfront</frameName>
            <robotNamespace>/</robotNamespace>
          </plugin>
          <pose>0.23725 0 0.261 0 -0 0</pose>
        </sensor>
        <kinematic>0</kinematic>
      </link>
      <link name='back_wheel_link'>
        <pose>-0.2502 0 0.0725 0 -0 0</pose>
        <inertial>
          <pose>0 0 0 0 -0 0</pose>
          <mass>0.2</mass>
          <inertia>
            <ixx>1</ixx>
            <ixy>0</ixy>
            <ixz>0</ixz>
            <iyy>1</iyy>
            <iyz>0</iyz>
            <izz>1</izz>
          </inertia>
        </inertial>
        <collision name='back_wheel_link_collision'>
          <pose>0 0 0 0 0 -1.5708</pose>
          <geometry>
            <mesh>
              <scale>0.1 0.1 0.1</scale>
              <uri>/home/parallels/teresa_catkin_pkgs/src/teresa_gazebo/meshes/teresa_wheel.dae</uri>
            </mesh>
          </geometry>
          <max_contacts>10</max_contacts>
          <surface>
            <bounce/>
            <friction>
              <ode/>
            </friction>
            <contact>
              <ode/>
            </contact>
          </surface>
        </collision>
        <visual name='back_wheel_link_visual'>
          <pose>0 0 0 0 0 -1.5708</pose>
          <geometry>
            <mesh>
              <scale>0.1 0.1 0.1</scale>
              <uri>/home/parallels/teresa_catkin_pkgs/src/teresa_gazebo/meshes/teresa_wheel.dae</uri>
            </mesh>
          </geometry>
        </visual>
        <velocity_decay>
          <linear>0</linear>
          <angular>0</angular>
        </velocity_decay>
        <self_collide>0</self_collide>
        <kinematic>0</kinematic>
        <gravity>1</gravity>
      </link>
      <joint name='body_to_back_wheel_joint' type='revolute'>
        <child>back_wheel_link</child>
        <parent>base_link</parent>
        <axis>
          <xyz>0 1 0</xyz>
          <limit>
            <lower>-1e+16</lower>
            <upper>1e+16</upper>
          </limit>
          <dynamics/>
        </axis>
      </joint>
      <link name='front_wheel_link'>
        <pose>0.2502 0 0.0725 0 -0 0</pose>
        <inertial>
          <pose>0 0 0 0 -0 0</pose>
          <mass>0.2</mass>
          <inertia>
            <ixx>1</ixx>
            <ixy>0</ixy>
            <ixz>0</ixz>
            <iyy>1</iyy>
            <iyz>0</iyz>
            <izz>1</izz>
          </inertia>
        </inertial>
        <collision name='front_wheel_link_collision'>
          <pose>0 0 0 0 0 -1.5708</pose>
          <geometry>
            <mesh>
              <scale>0.1 0.1 0.1</scale>
              <uri>/home/parallels/teresa_catkin_pkgs/src/teresa_gazebo/meshes/teresa_wheel.dae</uri>
            </mesh>
          </geometry>
          <max_contacts>10</max_contacts>
          <surface>
            <bounce/>
            <friction>
              <ode/>
            </friction>
            <contact>
              <ode/>
            </contact>
          </surface>
        </collision>
        <visual name='front_wheel_link_visual'>
          <pose>0 0 0 0 0 -1.5708</pose>
          <geometry>
            <mesh>
              <scale>0.1 0.1 0.1</scale>
              <uri>/home/parallels/teresa_catkin_pkgs/src/teresa_gazebo/meshes/teresa_wheel.dae</uri>
            </mesh>
          </geometry>
        </visual>
        <velocity_decay>
          <linear>0</linear>
          <angular>0</angular>
        </velocity_decay>
        <self_collide>0</self_collide>
        <kinematic>0</kinematic>
        <gravity>1</gravity>
      </link>
      <joint name='body_to_front_wheel_joint' type='revolute'>
        <child>front_wheel_link</child>
        <parent>base_link</parent>
        <axis>
          <xyz>0 1 0</xyz>
          <limit>
            <lower>-1e+16</lower>
            <upper>1e+16</upper>
          </limit>
          <dynamics/>
        </axis>
      </joint>
      <link name='left_wheel_link'>
        <pose>0 0.2502 0.0725 0 -0 0</pose>
        <inertial>
          <pose>0 0 0 0 -0 0</pose>
          <mass>0.2</mass>
          <inertia>
            <ixx>1</ixx>
            <ixy>0</ixy>
            <ixz>0</ixz>
            <iyy>1</iyy>
            <iyz>0</iyz>
            <izz>1</izz>
          </inertia>
        </inertial>
        <collision name='left_wheel_link_collision'>
          <pose>0 0 0 0 -0 1.5708</pose>
          <geometry>
            <mesh>
              <scale>0.1 0.1 0.1</scale>
              <uri>/home/parallels/teresa_catkin_pkgs/src/teresa_gazebo/meshes/teresa_wheel.dae</uri>
            </mesh>
          </geometry>
          <surface>
            <contact>
              <ode>
                <kp>1e+06</kp>
                <kd>100</kd>
                <max_vel>1</max_vel>
                <min_depth>0.001</min_depth>
              </ode>
            </contact>
            <friction>
              <ode>
                <mu>1</mu>
                <mu2>1</mu2>
              </ode>
            </friction>
            <bounce/>
          </surface>
          <max_contacts>10</max_contacts>
        </collision>
        <visual name='left_wheel_link_visual'>
          <pose>0 0 0 0 -0 1.5708</pose>
          <geometry>
            <mesh>
              <scale>0.1 0.1 0.1</scale>
              <uri>/home/parallels/teresa_catkin_pkgs/src/teresa_gazebo/meshes/teresa_wheel.dae</uri>
            </mesh>
          </geometry>
          <material>
            <script>
              <name>Gazebo/Black</name>
              <uri>__default__</uri>
            </script>
          </material>
        </visual>
        <gravity>1</gravity>
        <velocity_decay>
          <linear>0</linear>
          <angular>0</angular>
        </velocity_decay>
        <self_collide>0</self_collide>
        <kinematic>0</kinematic>
      </link>
      <joint name='body_to_left_wheel_joint' type='revolute'>
        <child>left_wheel_link</child>
        <parent>base_link</parent>
        <axis>
          <xyz>0 1 0</xyz>
          <limit>
            <lower>-1e+16</lower>
            <upper>1e+16</upper>
          </limit>
          <dynamics/>
        </axis>
      </joint>
      <link name='right_wheel_link'>
        <pose>0 -0.2502 0.0725 0 -0 0</pose>
        <inertial>
          <pose>0 0 0 0 -0 0</pose>
          <mass>0.2</mass>
          <inertia>
            <ixx>1</ixx>
            <ixy>0</ixy>
            <ixz>0</ixz>
            <iyy>1</iyy>
            <iyz>0</iyz>
            <izz>1</izz>
          </inertia>
        </inertial>
        <collision name='right_wheel_link_collision'>
          <pose>0 0 0 0 0 -1.5708</pose>
          <geometry>
            <mesh>
              <scale>0.1 0.1 0.1</scale>
              <uri>/home/parallels/teresa_catkin_pkgs/src/teresa_gazebo/meshes/teresa_wheel.dae</uri>
            </mesh>
          </geometry>
          <surface>
            <contact>
              <ode>
                <kp>1e+06</kp>
                <kd>100</kd>
                <max_vel>1</max_vel>
                <min_depth>0.001</min_depth>
              </ode>
            </contact>
            <friction>
              <ode>
                <mu>1</mu>
                <mu2>1</mu2>
              </ode>
            </friction>
            <bounce/>
          </surface>
          <max_contacts>10</max_contacts>
        </collision>
        <visual name='right_wheel_link_visual'>
          <pose>0 0 0 0 0 -1.5708</pose>
          <geometry>
            <mesh>
              <scale>0.1 0.1 0.1</scale>
              <uri>/home/parallels/teresa_catkin_pkgs/src/teresa_gazebo/meshes/teresa_wheel.dae</uri>
            </mesh>
          </geometry>
          <material>
            <script>
              <name>Gazebo/Black</name>
              <uri>__default__</uri>
            </script>
          </material>
        </visual>
        <gravity>1</gravity>
        <velocity_decay>
          <linear>0</linear>
          <angular>0</angular>
        </velocity_decay>
        <self_collide>0</self_collide>
        <kinematic>0</kinematic>
      </link>
      <joint name='body_to_right_wheel_joint' type='revolute'>
        <child>right_wheel_link</child>
        <parent>base_link</parent>
        <axis>
          <xyz>0 1 0</xyz>
          <limit>
            <lower>-1e+16</lower>
            <upper>1e+16</upper>
          </limit>
          <dynamics/>
        </axis>
      </joint>
      <link name='giraff_stalk'>
        <pose>0 0 1.303 0 -0 0</pose>
        <inertial>
          <pose>0.0225 0 -0.1875 0 -0 0</pose>
          <mass>0.2</mass>
          <inertia>
            <ixx>2.00703</ixx>
            <ixy>0</ixy>
            <ixz>0.00084375</ixz>
            <iyy>2.00713</iyy>
            <iyz>0</iyz>
            <izz>2.0001</izz>
          </inertia>
        </inertial>
        <collision name='giraff_stalk_collision'>
          <pose>0 0 0 0 0 -1.5708</pose>
          <geometry>
            <mesh>
              <scale>0.1 0.1 0.1</scale>
              <uri>/home/parallels/teresa_catkin_pkgs/src/teresa_gazebo/meshes/teresa_neck.dae</uri>
            </mesh>
          </geometry>
          <max_contacts>10</max_contacts>
          <surface>
            <bounce/>
            <friction>
              <ode/>
            </friction>
            <contact>
              <ode/>
            </contact>
          </surface>
        </collision>
        <visual name='giraff_stalk_visual'>
          <pose>0 0 0 0 0 -1.5708</pose>
          <geometry>
            <mesh>
              <scale>0.1 0.1 0.1</scale>
              <uri>/home/parallels/teresa_catkin_pkgs/src/teresa_gazebo/meshes/teresa_neck.dae</uri>
            </mesh>
          </geometry>
        </visual>
        <visual name='giraff_stalk_visual_xtionPeople_link'>
          <pose>0.045 0 -0.375 1.5708 -5.55112e-17 1.5708</pose>
          <geometry>
            <mesh>
              <scale>0.001 0.001 0.001</scale>
              <uri>/home/parallels/teresa_catkin_pkgs/src/teresa_gazebo/meshes/asus_xtion_pro_live.dae</uri>
            </mesh>
          </geometry>
        </visual>
        <velocity_decay>
          <linear>0</linear>
          <angular>0</angular>
        </velocity_decay>
        <self_collide>0</self_collide>
        <kinematic>0</kinematic>
        <gravity>1</gravity>
      </link>
      <joint name='body_to_stalk_joint' type='prismatic'>
        <child>giraff_stalk</child>
        <parent>base_link</parent>
        <axis>
          <xyz>0 0 1</xyz>
          <limit>
            <lower>-0.15</lower>
            <upper>0.1</upper>
            <effort>30</effort>
            <velocity>0.2</velocity>
          </limit>
          <dynamics/>
        </axis>
      </joint>
      <link name='giraff_head'>
        <pose>0 0 1.303 0 -0 0</pose>
        <inertial>
          <pose>0 0 0.1305 0 -0 0</pose>
          <mass>0.2</mass>
          <inertia>
            <ixx>2.00341</ixx>
            <ixy>0</ixy>
            <ixz>0</ixz>
            <iyy>2.00341</iyy>
            <iyz>0</iyz>
            <izz>2</izz>
          </inertia>
        </inertial>
        <collision name='giraff_head_collision'>
          <pose>0 0 0 0 0 -1.5708</pose>
          <geometry>
            <mesh>
              <scale>0.1 0.1 0.1</scale>
              <uri>/home/parallels/teresa_catkin_pkgs/src/teresa_gazebo/meshes/teresa_head.dae</uri>
            </mesh>
          </geometry>
          <surface>
            <contact>
              <ode/>
            </contact>
            <friction>
              <ode>
                <mu>1</mu>
                <mu2>0</mu2>
              </ode>
            </friction>
            <bounce/>
          </surface>
          <max_contacts>10</max_contacts>
        </collision>
        <visual name='giraff_head_visual'>
          <pose>0 0 0 0 0 -1.5708</pose>
          <geometry>
            <mesh>
              <scale>0.1 0.1 0.1</scale>
              <uri>/home/parallels/teresa_catkin_pkgs/src/teresa_gazebo/meshes/teresa_head.dae</uri>
            </mesh>
          </geometry>
          <material>
            <script>
              <name>Gazebo/Blue</name>
              <uri>__default__</uri>
            </script>
          </material>
        </visual>
        <velocity_decay>
          <linear>0</linear>
          <angular>0</angular>
        </velocity_decay>
        <gravity>1</gravity>
        <velocity_decay>
          <linear>0</linear>
          <angular>0</angular>
        </velocity_decay>
        <self_collide>0</self_collide>
        <sensor name='head_camera' type='camera'>
          <update_rate>30</update_rate>
          <camera name='head_camera'>
            <horizontal_fov>1.39626</horizontal_fov>
            <image>
              <width>800</width>
              <height>800</height>
              <format>R8G8B8</format>
            </image>
            <clip>
              <near>0.02</near>
              <far>300</far>
            </clip>
            <noise>
              <type>gaussian</type>
              <mean>0</mean>
              <stddev>0.007</stddev>
            </noise>
          </camera>
          <plugin name='camera_controller' filename='libgazebo_ros_camera.so'>
            <alwaysOn>true</alwaysOn>
            <updateRate>0.0</updateRate>
            <cameraName>teresa_robot/head_camera</cameraName>
            <imageTopicName>image_raw</imageTopicName>
            <cameraInfoTopicName>camera_info</cameraInfoTopicName>
            <frameName>camera_link</frameName>
            <hackBaseline>0.07</hackBaseline>
            <distortionK1>0.0</distortionK1>
            <distortionK2>0.0</distortionK2>
            <distortionK3>0.0</distortionK3>
            <distortionT1>0.0</distortionT1>
            <distortionT2>0.0</distortionT2>
            <robotNamespace>/</robotNamespace>
          </plugin>
          <pose>0 0 0.261 0 -0 0</pose>
        </sensor>
        <kinematic>0</kinematic>
      </link>
      <joint name='stalk_to_head_joint' type='revolute'>
        <child>giraff_head</child>
        <parent>giraff_stalk</parent>
        <axis>
          <xyz>0 1 0</xyz>
          <limit>
            <lower>-1.57</lower>
            <upper>1.57</upper>
            <effort>30</effort>
            <velocity>0.2</velocity>
          </limit>
          <dynamics/>
        </axis>
      </joint>
      <plugin name='gazebo_ros_control' filename='libgazebo_ros_control.so'>
        <robotNamespace>/teresa_robot</robotNamespace>
      </plugin>
      <plugin name='differential_drive_controller' filename='libgazebo_ros_diff_drive.so'>
        <alwaysOn>true</alwaysOn>
        <updateRate>30</updateRate>
        <leftJoint>body_to_right_wheel_joint</leftJoint>
        <rightJoint>body_to_left_wheel_joint</rightJoint>
        <wheelSeparation>0.504</wheelSeparation>
        <wheelDiameter>0.145</wheelDiameter>
        <torque>20</torque>
        <commandTopic>cmd_vel</commandTopic>
        <odometryTopic>odom</odometryTopic>
        <odometryFrame>odom</odometryFrame>
        <robotBaseFrame>base_link</robotBaseFrame>
        <robotNamespace>/</robotNamespace>
      </plugin>
      <static>0</static>
      <plugin name='odometry' filename='libgazebo_ros_p3d.so'>
        <alwaysOn>true</alwaysOn>
        <frameName>map</frameName>
        <bodyName>base_link</bodyName>
        <topicName>/odom</topicName>
        <updateRate>30.0</updateRate>
        <robotNamespace>/</robotNamespace>
      </plugin>
      <pose>0 0 0 0 -0 0</pose>
    </model>
    <state world_name='default'>
      <sim_time>134 685000000</sim_time>
      <real_time>105 368916312</real_time>
      <wall_time>1459506967 477481740</wall_time>
      <model name='heightmap'>
        <pose>0 0 0 0 -0 0</pose>
        <link name='link'>
          <pose>0 0 0 0 -0 0</pose>
          <velocity>0 0 0 0 -0 0</velocity>
          <acceleration>0 0 0 0 -0 0</acceleration>
          <wrench>0 0 0 0 -0 0</wrench>
        </link>
      </model>
      <model name='teresa_robot'>
        <pose>-0.000328 6.9e-05 -8.9e-05 -5.6e-05 -7e-06 0.000109</pose>
        <link name='back_wheel_link'>
          <pose>-0.250529 4.6e-05 0.072438 -5.6e-05 -0.019983 0.00011</pose>
          <velocity>9.1e-05 8e-06 0.003455 -0.000105 0.001259 2e-06</velocity>
          <acceleration>0 0 0 0 -0 0</acceleration>
          <wrench>0 0 0 0 -0 0</wrench>
        </link>
        <link name='base_link'>
          <pose>-0.000328 6.9e-05 -8.9e-05 -5.6e-05 -7e-06 0.000109</pose>
          <velocity>4.7e-05 6e-06 0.002472 -0.000105 5.8e-05 2e-06</velocity>
          <acceleration>0 0 0 0 -0 0</acceleration>
          <wrench>0 0 0 0 -0 0</wrench>
        </link>
        <link name='front_wheel_link'>
          <pose>0.249872 0.0001 0.072438 -5.5e-05 -0.019956 0.00011</pose>
          <velocity>0.000116 8e-06 0.003349 -0.000105 0.001602 2e-06</velocity>
          <acceleration>0 0 0 0 -0 0</acceleration>
          <wrench>0 0 0 0 -0 0</wrench>
        </link>
        <link name='giraff_head'>
          <pose>-0.000337 0.000142 1.30291 -5.6e-05 -7e-06 0.000109</pose>
          <velocity>0.000121 0.000145 0.002584 -0.000106 5.5e-05 2e-06</velocity>
          <acceleration>0 0 0 0 -0 0</acceleration>
          <wrench>0 0 0 0 -0 0</wrench>
        </link>
        <link name='giraff_stalk'>
          <pose>-0.000337 0.000142 1.30291 -5.6e-05 -7e-06 0.000109</pose>
          <velocity>0.000121 0.000142 0.002462 -0.000106 5.7e-05 2e-06</velocity>
          <acceleration>0 0 0 0 -0 0</acceleration>
          <wrench>0 0 0 0 -0 0</wrench>
        </link>
        <link name='left_wheel_link'>
          <pose>-0.000356 0.25025 0.07242 -5.6e-05 -0.000159 0.000109</pose>
          <velocity>4e-06 8e-06 0.000123 -0.000105 5.6e-05 2e-06</velocity>
          <acceleration>0 0 0 0 -0 0</acceleration>
          <wrench>0 0 0 0 -0 0</wrench>
        </link>
        <link name='right_wheel_link'>
          <pose>-0.000302 -0.250107 0.072415 -5.5e-05 -0.000163 0.000109</pose>
          <velocity>4e-06 4e-06 0.000146 -5.2e-05 5.7e-05 2e-06</velocity>
          <acceleration>0 0 0 0 -0 0</acceleration>
          <wrench>0 0 0 0 -0 0</wrench>
        </link>
      </model>
    </state>
    <gui fullscreen='0'>
      <camera name='user_camera'>
        <pose>5 -5 2 0 0.275643 2.35619</pose>
        <view_controller>orbit</view_controller>
      </camera>
    </gui>
  </world>
</sdf>
