<?xml version="1.0" ?>
<!-- =================================================================================== -->
<!-- |    This document was autogenerated by xacro from teresa_robot.urdf.xacro        | -->
<!-- |    EDITING THIS FILE BY HAND IS NOT RECOMMENDED                                 | -->
<!-- =================================================================================== -->
<robot name="teresa_robot" xmlns:xacro="http://www.ros.org/wiki/xacro">
  <gazebo reference="base_link">
    <mu1>0.0</mu1>
    <mu2>0.0</mu2>
    <material>Gazebo/Blue</material>
  </gazebo>
  <gazebo reference="left_wheel_link">
    <!--fdir1 value="1 0 0"/-->
    <mu1>1.0</mu1>
    <mu2>1.0</mu2>
    <kp>1000000.0</kp>
    <kd>100.0</kd>
    <minDepth>0.001</minDepth>
    <maxVel>1.0</maxVel>
    <material>Gazebo/Black</material>
  </gazebo>
  <gazebo reference="right_wheel_link">
    <!--fdir1 value="1 0 0"/-->
    <mu1>1.0</mu1>
    <mu2>1.0</mu2>
    <kp>1000000.0</kp>
    <kd>100.0</kd>
    <minDepth>0.001</minDepth>
    <maxVel>1.0</maxVel>
    <material>Gazebo/Black</material>
  </gazebo>
  <gazebo reference="front_wheel_link">
    <!--fdir1 value="1 0 0"/-->
    <mu1>0.0</mu1>
    <mu2>0.0</mu2>
    <kp>1000000.0</kp>
    <kd>100.0</kd>
    <minDepth>0.001</minDepth>
    <maxVel>1.0</maxVel>
    <material>Gazebo/Black</material>
  </gazebo>  
  <gazebo reference="back_wheel_link">
    <!--fdir1 value="1 0 0"/-->
    <mu1>0.0</mu1>
    <mu2>0.0</mu2>
    <kp>1000000.0</kp>
    <kd>100.0</kd>
    <minDepth>0.001</minDepth>
    <maxVel>1.0</maxVel>
    <material>Gazebo/Black</material>
  </gazebo>
  <gazebo reference="giraff_head">
    <mu1>1.0</mu1>
    <mu2>0.0</mu2>
    <material>Gazebo/Blue</material>
  </gazebo>
  <gazebo>
    <plugin filename="libgazebo_ros_control.so" name="gazebo_ros_control">
      <robotNamespace>/teresa_robot</robotNamespace>
      <robotSimType>gazebo_ros_control/DefaultRobotHWSim</robotSimType>
    </plugin>
  </gazebo>
  <!--gazebo>
    <plugin name="differential_drive_controller" filename="libgazebo_ros_diff_drive.so">
      <alwaysOn>true</alwaysOn>
      <updateRate>30</updateRate>
      <leftJoint>body_to_right_wheel_joint</leftJoint>
      <rightJoint>body_to_left_wheel_joint</rightJoint>
      <wheelSeparation>0.504</wheelSeparation>
      <wheelDiameter>0.145</wheelDiameter>
      <torque>20</torque>
      <commandTopic>cmd_vel</commandTopic>
      <odometryTopic>odom</odometryTopic>
      <odometryFrame>odom</odometryFrame>
      <robotBaseFrame>base_link</robotBaseFrame>
    </plugin>
  </gazebo-->
  <gazebo>
    <plugin filename="libgazebo_ros_p3d.so" name="odometry">
      <alwaysOn>true</alwaysOn>
      <frameName>map</frameName>
      <bodyName>base_link</bodyName>
      <topicName>/odom</topicName>
     <gaussianNoise>0.001</gaussianNoise>
      <updateRate>30.0</updateRate>
    </plugin>
  </gazebo>
  <gazebo reference="laserfront">
    <sensor name="hokuyo_front_sensor" type="ray">
      <pose>0 0 0 0 0 0</pose>
      <visualize>false</visualize>
      <update_rate>40</update_rate>
      <ray>
        <scan>
          <horizontal>
            <samples>720</samples>
            <resolution>1</resolution>
            <min_angle>-1.570796</min_angle>
            <max_angle>1.570796</max_angle>
          </horizontal>
        </scan>
        <range>
          <min>0.10</min>
          <max>4.0</max>
          <resolution>0.01</resolution>
        </range>
        <noise>
          <type>gaussian</type>
          <mean>0.0</mean>
          <stddev>0.01</stddev>
        </noise>
      </ray>
      <plugin filename="libgazebo_ros_laser.so" name="gazebo_ros_head_hokuyo_controller">
        <topicName>/scanfront</topicName>
        <frameName>laserfront</frameName>
      </plugin>
    </sensor>
  </gazebo>
  <gazebo reference="laserback">
    <sensor name="hokuyo_back_sensor" type="ray">
      <pose>0 0 0 0 0 0</pose>
      <visualize>false</visualize>
      <update_rate>40</update_rate>
      <ray>
        <scan>
          <horizontal>
            <samples>720</samples>
            <resolution>1</resolution>
            <min_angle>-1.570796</min_angle>
            <max_angle>1.570796</max_angle>
          </horizontal>
        </scan>
        <range>
          <min>0.10</min>
          <max>4.0</max>
          <resolution>0.01</resolution>
        </range>
        <noise>
          <type>gaussian</type>
          <mean>0.0</mean>
          <stddev>0.01</stddev>
        </noise>
      </ray>
      <plugin filename="libgazebo_ros_laser.so" name="gazebo_ros_head_hokuyo_controller">
        <topicName>/scanback</topicName>
        <frameName>laserback</frameName>
      </plugin>
    </sensor>
  </gazebo>
  <!-- camera -->
  <gazebo reference="head_camera">
    <sensor name="head_camera" type="camera">
      <update_rate>30.0</update_rate>
      <camera name="head_camera">
        <horizontal_fov>1.3962634</horizontal_fov>
        <image>
          <width>800</width>
          <height>800</height>
          <format>R8G8B8</format>
        </image>
        <clip>
          <near>0.02</near>
          <far>300</far>
        </clip>
        <noise>
          <type>gaussian</type>
          <mean>0.0</mean>
          <stddev>0.007</stddev>
        </noise>
      </camera>
      <plugin filename="libgazebo_ros_camera.so" name="camera_controller">
        <alwaysOn>true</alwaysOn>
        <updateRate>0.0</updateRate>
        <cameraName>rrbot/camera1</cameraName>
        <imageTopicName>image_raw</imageTopicName>
        <cameraInfoTopicName>camera_info</cameraInfoTopicName>
        <frameName>camera_link</frameName>
        <hackBaseline>0.07</hackBaseline>
        <distortionK1>0.0</distortionK1>
        <distortionK2>0.0</distortionK2>
        <distortionK3>0.0</distortionK3>
        <distortionT1>0.0</distortionT1>
        <distortionT2>0.0</distortionT2>
      </plugin>
    </sensor>
  </gazebo>
  <material name="black">
    <color rgba="0.0 0.0 0.0 1.0"/>
  </material>
  <material name="blue">
    <color rgba="0.0 0.0 0.8 1.0"/>
  </material>
  <material name="green">
    <color rgba="0.0 0.8 0.0 1.0"/>
  </material>
  <material name="grey">
    <color rgba="0.2 0.2 0.2 1.0"/>
  </material>
  <material name="orange">
    <color rgba="1.0 0.423529411765 0.0392156862745 1.0"/>
  </material>
  <material name="brown">
    <color rgba="0.870588235294 0.811764705882 0.764705882353 1.0"/>
  </material>
  <material name="red">
    <color rgba="0.8 0.0 0.0 1.0"/>
  </material>
  <material name="white">
    <color rgba="1.0 1.0 1.0 1.0"/>
  </material>
  <link name="base_link">
    <collision>
      <origin rpy="0 0 -1.57079632679" xyz="0.0 0.0 0.336"/>
      <geometry>
        <mesh filename="package://teresa_gazebo/meshes/teresa_body.dae" scale="0.1 0.1 0.1"/>
      </geometry>
    </collision>
    <visual>
      <origin rpy="0 0 -1.57079632679" xyz="0.0 0.0 0.336"/>
      <geometry>
        <mesh filename="package://teresa_gazebo/meshes/teresa_body.dae" scale="0.1 0.1 0.1"/>
      </geometry>
      <material name="blue"/>
    </visual>
    <inertial>
      <origin rpy="0.0 0.0 0.0" xyz="0.0 0.0 0.336"/>
      <mass value="10.0"/>
      <inertia ixx="1.0" ixy="0.0" ixz="0.0" iyy="1.0" iyz="0.0" izz="1.0"/>
    </inertial>
  </link>
  <link name="left_wheel_link">
    <visual>
      <origin rpy="0 0 1.57079632679" xyz="0.0 0.0 0.0"/>
      <geometry>
        <mesh filename="package://teresa_gazebo/meshes/teresa_wheel.dae" scale="0.1 0.1 0.1"/>
      </geometry>
    </visual>
    <collision>
      <origin rpy="0 0 1.57079632679" xyz="0.0 0.0 0.0"/>
      <geometry>
        <mesh filename="package://teresa_gazebo/meshes/teresa_wheel.dae" scale="0.1 0.1 0.1"/>
      </geometry>
    </collision>
    <inertial>
      <mass value="0.2"/>
      <origin rpy="0 0 0" xyz="0.0 0.0 0.0"/>
      <inertia ixx="1.0" ixy="0.0" ixz="0.0" iyy="1.0" iyz="0.0" izz="1.0"/>
    </inertial>
  </link>
  <link name="right_wheel_link">
    <visual>
      <origin rpy="0 0 -1.57079632679" xyz="0.0 0.0 0.0"/>
      <geometry>
        <mesh filename="package://teresa_gazebo/meshes/teresa_wheel.dae" scale="0.1 0.1 0.1"/>
      </geometry>
    </visual>
    <collision>
      <origin rpy="0 0 -1.57079632679" xyz="0.0 0.0 0.0"/>
      <geometry>
        <mesh filename="package://teresa_gazebo/meshes/teresa_wheel.dae" scale="0.1 0.1 0.1"/>
      </geometry>
    </collision>
    <inertial>
      <mass value="0.2"/>
      <origin rpy="0 0 0" xyz="0.0 0.0 0.0"/>
      <inertia ixx="1.0" ixy="0.0" ixz="0.0" iyy="1.0" iyz="0.0" izz="1.0"/>
    </inertial>
  </link>
  <link name="giraff_stalk">
    <visual>
      <origin rpy="0 0 -1.57079632679" xyz="0.0 0.0 0.0"/>
      <geometry>
        <mesh filename="package://teresa_gazebo/meshes/teresa_neck.dae" scale="0.1 0.1 0.1"/>
      </geometry>
    </visual>
    <collision>
      <origin rpy="0 0 -1.57079632679" xyz="0.0 0.0 0.0"/>
      <geometry>
        <mesh filename="package://teresa_gazebo/meshes/teresa_neck.dae" scale="0.1 0.1 0.1"/>
      </geometry>
    </collision>
    <inertial>
      <mass value="2.0"/>
      <origin rpy="0 0 0" xyz="0.0 0.0 0.0"/>
      <inertia ixx="1.0" ixy="0.0" ixz="0.0" iyy="1.0" iyz="0.0" izz="1.0"/>
    </inertial>
  </link>
  <link name="giraff_head">
    <visual>
      <origin rpy="0 0 -1.57079632679" xyz="0.0 0.0 0.0"/>
      <geometry>
        <mesh filename="package://teresa_gazebo/meshes/teresa_head.dae" scale="0.1 0.1 0.1"/>
      </geometry>
    </visual>
    <collision>
      <origin rpy="0 0 -1.57079632679" xyz="0.0 0.0 0.0"/>
      <geometry>
        <mesh filename="package://teresa_gazebo/meshes/teresa_head.dae" scale="0.1 0.1 0.1"/>
      </geometry>
    </collision>
    <inertial>
      <mass value="1.0"/>
      <origin rpy="0 0 0" xyz="0.0 0.0 0.0"/>
      <inertia ixx="1.0" ixy="0.0" ixz="0.0" iyy="1.0" iyz="0.0" izz="1.0"/>
    </inertial>
  </link>
  <link name="laserfront">
    <visual>
      <geometry>
        <mesh filename="package://teresa_gazebo/meshes/hokuyo.dae"/>
      </geometry>
    </visual>
    <inertial>
      <mass value="0.1"/>
      <origin xyz="0.0 0.0 0.0"/>
      <inertia ixx="1.0" ixy="0.0" ixz="0.0" iyy="1.0" iyz="0.0" izz="1.0"/>
    </inertial>
  </link>
  <link name="laserback">
    <visual>
      <geometry>
        <mesh filename="package://teresa_gazebo/meshes/hokuyo.dae"/>
      </geometry>
    </visual>
    <inertial>
      <mass value="0.1"/>
      <origin xyz="0.0 0.0 0.0"/>
      <inertia ixx="1.0" ixy="0.0" ixz="0.0" iyy="1.0" iyz="0.0" izz="1.0"/>
    </inertial>
  </link>
  <link name="head_camera">
    <inertial>
      <mass value="0.1"/>
      <origin xyz="0.0 0.0 0.0"/>
      <inertia ixx="1.0" ixy="0.0" ixz="0.0" iyy="1.0" iyz="0.0" izz="1.0"/>
    </inertial>
  </link>
  <link name="xtionPeople_link">
    <visual>
      <geometry>
        <mesh filename="package://teresa_gazebo/meshes/asus_xtion_pro_live.dae" scale="0.001 0.001 0.001"/>
      </geometry>
      <origin rpy="1.57079632679 0 1.57079632679" xyz="0.0 0 0.0"/>
    </visual>
    <inertial>
      <mass value="0.1"/>
      <origin xyz="0.0 0.0 0.0"/>
      <inertia ixx="1.0" ixy="0.0" ixz="0.0" iyy="1.0" iyz="0.0" izz="1.0"/>
    </inertial>
  </link>
  <joint name="body_to_hokuyo_front_joint" type="fixed">
    <parent link="base_link"/>
    <child link="laserfront"/>
    <origin xyz="0.23725 0 0.261"/>
  </joint>
  <joint name="body_to_hokuyo_back_joint" type="fixed">
    <parent link="base_link"/>
    <child link="laserback"/>
    <origin rpy="0 0 3.14159265359" xyz="-0.23725 0 0.261"/>
  </joint>
  <joint name="stalk_to_xtion_people_joint" type="fixed">
    <parent link="giraff_stalk"/>
    <child link="xtionPeople_link"/>
    <origin xyz="0.045 0.0 -0.375"/>
  </joint>
  <joint name="body_to_left_wheel_joint" type="continuous">
    <axis xyz="0 1 0"/>
    <parent link="base_link"/>
    <child link="left_wheel_link"/>
    <origin xyz="0 0.2502 0.0725"/>
  </joint>
  <joint name="body_to_right_wheel_joint" type="continuous">
    <parent link="base_link"/>
    <child link="right_wheel_link"/>
    <origin rpy="0.0 0.0 0.0" xyz="0 -0.2502 0.0725"/>
    <axis xyz="0 1 0"/>
  </joint>
  <joint name="body_to_stalk_joint" type="prismatic">
    <axis xyz="0 0 1"/>
    <parent link="base_link"/>
    <child link="giraff_stalk"/>
    <origin xyz="0 0.0 1.403"/>
    <limit effort="30" lower="-0.2" upper="0.2" velocity="0.2"/>
  </joint>
  <joint name="stalk_to_head_joint" type="revolute">
    <axis xyz="0 1 0"/>
    <parent link="giraff_stalk"/>
    <child link="giraff_head"/>
    <origin xyz="0 0.0 0.0"/>
    <limit effort="30" lower="-0.2" upper="0.15" velocity="0.2"/>
  </joint>
  <joint name="head_to_cam_joint" type="fixed">
    <parent link="giraff_head"/>
    <child link="head_camera"/>
    <origin xyz="0 0 0.261"/>
  </joint>
  <!--transmission name="tran1">
    <type>transmission_interface/SimpleTransmission</type>
    <joint name="body_to_left_wheel_joint">
      <hardwareInterface>VelocityJointInterface</hardwareInterface>
    </joint>
    <actuator name="left_motor">
      <hardwareInterface>VelocityJointInterface</hardwareInterface>
      <mechanicalReduction>100</mechanicalReduction>
    </actuator>
  </transmission-->
  <!--transmission name="tran2">
    <type>transmission_interface/SimpleTransmission</type>
    <joint name="body_to_right_wheel_joint">
      <hardwareInterface>VelocityJointInterface</hardwareInterface>
    </joint>
    <actuator name="right_motor">
      <hardwareInterface>VelocityJointInterface</hardwareInterface>
      <mechanicalReduction>100</mechanicalReduction>
    </actuator>
  </transmission-->
  <transmission name="tran1">
    <type>transmission_interface/SimpleTransmission</type>
    <joint name="stalk_to_head_joint">
      <hardwareInterface>EffortJointInterface</hardwareInterface>
    </joint>
    <actuator name="head_motor">
      <hardwareInterface>EffortJointInterface</hardwareInterface>
      <mechanicalReduction>100</mechanicalReduction>
    </actuator>
  </transmission>
</robot>

